[2023-07-11T13:39:22.734+0000] {taskinstance.py:1103} INFO - Dependencies all met for dep_context=non-requeueable deps ti=<TaskInstance: exercice_1.save_data scheduled__2023-07-01T00:00:00+00:00 [queued]>
[2023-07-11T13:39:22.782+0000] {taskinstance.py:1103} INFO - Dependencies all met for dep_context=requeueable deps ti=<TaskInstance: exercice_1.save_data scheduled__2023-07-01T00:00:00+00:00 [queued]>
[2023-07-11T13:39:22.797+0000] {taskinstance.py:1308} INFO - Starting attempt 1 of 2
[2023-07-11T13:39:22.881+0000] {taskinstance.py:1327} INFO - Executing <Task(PythonOperator): save_data> on 2023-07-01 00:00:00+00:00
[2023-07-11T13:39:22.890+0000] {standard_task_runner.py:57} INFO - Started process 6398 to run task
[2023-07-11T13:39:22.908+0000] {standard_task_runner.py:84} INFO - Running: ['***', 'tasks', 'run', 'exercice_1', 'save_data', 'scheduled__2023-07-01T00:00:00+00:00', '--job-id', '121', '--raw', '--subdir', 'DAGS_FOLDER/correction.py', '--cfg-path', '/tmp/tmpq0lq2b8c']
[2023-07-11T13:39:22.921+0000] {standard_task_runner.py:85} INFO - Job 121: Subtask save_data
[2023-07-11T13:39:23.168+0000] {task_command.py:410} INFO - Running <TaskInstance: exercice_1.save_data scheduled__2023-07-01T00:00:00+00:00 [running]> on host 1d6232dcfa4d
[2023-07-11T13:39:23.452+0000] {taskinstance.py:1547} INFO - Exporting env vars: AIRFLOW_CTX_DAG_OWNER='***' AIRFLOW_CTX_DAG_ID='exercice_1' AIRFLOW_CTX_TASK_ID='save_data' AIRFLOW_CTX_EXECUTION_DATE='2023-07-01T00:00:00+00:00' AIRFLOW_CTX_TRY_NUMBER='1' AIRFLOW_CTX_DAG_RUN_ID='scheduled__2023-07-01T00:00:00+00:00'
[2023-07-11T13:39:23.474+0000] {taskinstance.py:1824} ERROR - Task failed with exception
Traceback (most recent call last):
  File "/home/airflow/.local/lib/python3.7/site-packages/airflow/operators/python.py", line 181, in execute
    return_value = self.execute_callable()
  File "/home/airflow/.local/lib/python3.7/site-packages/airflow/operators/python.py", line 198, in execute_callable
    return self.python_callable(*self.op_args, **self.op_kwargs)
  File "/opt/airflow/dags/correction.py", line 11, in save_inFile
    .format(context["execution_date"], nb_random())
NameError: name 'nb_random' is not defined
[2023-07-11T13:39:23.539+0000] {taskinstance.py:1350} INFO - Marking task as UP_FOR_RETRY. dag_id=exercice_1, task_id=save_data, execution_date=20230701T000000, start_date=20230711T133922, end_date=20230711T133923
[2023-07-11T13:39:23.598+0000] {standard_task_runner.py:109} ERROR - Failed to execute job 121 for task save_data (name 'nb_random' is not defined; 6398)
[2023-07-11T13:39:23.617+0000] {local_task_job_runner.py:225} INFO - Task exited with return code 1
[2023-07-11T13:39:23.678+0000] {taskinstance.py:2653} INFO - 0 downstream tasks scheduled from follow-on schedule check
[2023-07-11T13:42:04.277+0000] {taskinstance.py:1103} INFO - Dependencies all met for dep_context=non-requeueable deps ti=<TaskInstance: exercice_1.save_data scheduled__2023-07-01T00:00:00+00:00 [queued]>
[2023-07-11T13:42:04.309+0000] {taskinstance.py:1103} INFO - Dependencies all met for dep_context=requeueable deps ti=<TaskInstance: exercice_1.save_data scheduled__2023-07-01T00:00:00+00:00 [queued]>
[2023-07-11T13:42:04.310+0000] {taskinstance.py:1308} INFO - Starting attempt 1 of 2
[2023-07-11T13:42:04.379+0000] {taskinstance.py:1327} INFO - Executing <Task(PythonOperator): save_data> on 2023-07-01 00:00:00+00:00
[2023-07-11T13:42:04.395+0000] {standard_task_runner.py:57} INFO - Started process 6522 to run task
[2023-07-11T13:42:04.412+0000] {standard_task_runner.py:84} INFO - Running: ['***', 'tasks', 'run', 'exercice_1', 'save_data', 'scheduled__2023-07-01T00:00:00+00:00', '--job-id', '147', '--raw', '--subdir', 'DAGS_FOLDER/correction.py', '--cfg-path', '/tmp/tmp06qah41l']
[2023-07-11T13:42:04.419+0000] {standard_task_runner.py:85} INFO - Job 147: Subtask save_data
[2023-07-11T13:42:04.561+0000] {task_command.py:410} INFO - Running <TaskInstance: exercice_1.save_data scheduled__2023-07-01T00:00:00+00:00 [running]> on host 1d6232dcfa4d
[2023-07-11T13:42:04.779+0000] {taskinstance.py:1547} INFO - Exporting env vars: AIRFLOW_CTX_DAG_OWNER='***' AIRFLOW_CTX_DAG_ID='exercice_1' AIRFLOW_CTX_TASK_ID='save_data' AIRFLOW_CTX_EXECUTION_DATE='2023-07-01T00:00:00+00:00' AIRFLOW_CTX_TRY_NUMBER='1' AIRFLOW_CTX_DAG_RUN_ID='scheduled__2023-07-01T00:00:00+00:00'
[2023-07-11T13:42:04.815+0000] {taskinstance.py:1824} ERROR - Task failed with exception
Traceback (most recent call last):
  File "/home/airflow/.local/lib/python3.7/site-packages/airflow/operators/python.py", line 181, in execute
    return_value = self.execute_callable()
  File "/home/airflow/.local/lib/python3.7/site-packages/airflow/operators/python.py", line 198, in execute_callable
    return self.python_callable(*self.op_args, **self.op_kwargs)
  File "/opt/airflow/dags/correction.py", line 11, in save_inFile
    .format(context["execution_date"], nb_random())
NameError: name 'nb_random' is not defined
[2023-07-11T13:42:04.862+0000] {taskinstance.py:1350} INFO - Marking task as UP_FOR_RETRY. dag_id=exercice_1, task_id=save_data, execution_date=20230701T000000, start_date=20230711T134204, end_date=20230711T134204
[2023-07-11T13:42:04.940+0000] {standard_task_runner.py:109} ERROR - Failed to execute job 147 for task save_data (name 'nb_random' is not defined; 6522)
[2023-07-11T13:42:04.975+0000] {local_task_job_runner.py:225} INFO - Task exited with return code 1
[2023-07-11T13:42:05.040+0000] {taskinstance.py:2653} INFO - 0 downstream tasks scheduled from follow-on schedule check
[2023-07-11T13:48:20.504+0000] {taskinstance.py:1103} INFO - Dependencies all met for dep_context=non-requeueable deps ti=<TaskInstance: exercice_1.save_data scheduled__2023-07-01T00:00:00+00:00 [queued]>
[2023-07-11T13:48:20.584+0000] {taskinstance.py:1103} INFO - Dependencies all met for dep_context=requeueable deps ti=<TaskInstance: exercice_1.save_data scheduled__2023-07-01T00:00:00+00:00 [queued]>
[2023-07-11T13:48:20.585+0000] {taskinstance.py:1308} INFO - Starting attempt 1 of 2
[2023-07-11T13:48:20.664+0000] {taskinstance.py:1327} INFO - Executing <Task(PythonOperator): save_data> on 2023-07-01 00:00:00+00:00
[2023-07-11T13:48:20.682+0000] {standard_task_runner.py:57} INFO - Started process 6712 to run task
[2023-07-11T13:48:20.699+0000] {standard_task_runner.py:84} INFO - Running: ['***', 'tasks', 'run', 'exercice_1', 'save_data', 'scheduled__2023-07-01T00:00:00+00:00', '--job-id', '169', '--raw', '--subdir', 'DAGS_FOLDER/correction.py', '--cfg-path', '/tmp/tmpzerjp0v1']
[2023-07-11T13:48:20.709+0000] {standard_task_runner.py:85} INFO - Job 169: Subtask save_data
[2023-07-11T13:48:20.895+0000] {task_command.py:410} INFO - Running <TaskInstance: exercice_1.save_data scheduled__2023-07-01T00:00:00+00:00 [running]> on host 1d6232dcfa4d
[2023-07-11T13:48:21.266+0000] {taskinstance.py:1547} INFO - Exporting env vars: AIRFLOW_CTX_DAG_OWNER='***' AIRFLOW_CTX_DAG_ID='exercice_1' AIRFLOW_CTX_TASK_ID='save_data' AIRFLOW_CTX_EXECUTION_DATE='2023-07-01T00:00:00+00:00' AIRFLOW_CTX_TRY_NUMBER='1' AIRFLOW_CTX_DAG_RUN_ID='scheduled__2023-07-01T00:00:00+00:00'
[2023-07-11T13:48:21.281+0000] {taskinstance.py:1824} ERROR - Task failed with exception
Traceback (most recent call last):
  File "/home/airflow/.local/lib/python3.7/site-packages/airflow/operators/python.py", line 181, in execute
    return_value = self.execute_callable()
  File "/home/airflow/.local/lib/python3.7/site-packages/airflow/operators/python.py", line 198, in execute_callable
    return self.python_callable(*self.op_args, **self.op_kwargs)
  File "/opt/airflow/dags/correction.py", line 11, in save_inFile
    .format(context["execution_date"], nb_random())
NameError: name 'nb_random' is not defined
[2023-07-11T13:48:21.306+0000] {taskinstance.py:1350} INFO - Marking task as UP_FOR_RETRY. dag_id=exercice_1, task_id=save_data, execution_date=20230701T000000, start_date=20230711T134820, end_date=20230711T134821
[2023-07-11T13:48:21.378+0000] {standard_task_runner.py:109} ERROR - Failed to execute job 169 for task save_data (name 'nb_random' is not defined; 6712)
[2023-07-11T13:48:21.432+0000] {local_task_job_runner.py:225} INFO - Task exited with return code 1
[2023-07-11T13:48:21.488+0000] {taskinstance.py:2653} INFO - 0 downstream tasks scheduled from follow-on schedule check
[2023-07-11T13:51:19.049+0000] {taskinstance.py:1103} INFO - Dependencies all met for dep_context=non-requeueable deps ti=<TaskInstance: exercice_1.save_data scheduled__2023-07-01T00:00:00+00:00 [queued]>
[2023-07-11T13:51:19.080+0000] {taskinstance.py:1103} INFO - Dependencies all met for dep_context=requeueable deps ti=<TaskInstance: exercice_1.save_data scheduled__2023-07-01T00:00:00+00:00 [queued]>
[2023-07-11T13:51:19.081+0000] {taskinstance.py:1308} INFO - Starting attempt 1 of 2
[2023-07-11T13:51:19.153+0000] {taskinstance.py:1327} INFO - Executing <Task(PythonOperator): save_data> on 2023-07-01 00:00:00+00:00
[2023-07-11T13:51:19.187+0000] {standard_task_runner.py:57} INFO - Started process 6840 to run task
[2023-07-11T13:51:19.227+0000] {standard_task_runner.py:84} INFO - Running: ['***', 'tasks', 'run', 'exercice_1', 'save_data', 'scheduled__2023-07-01T00:00:00+00:00', '--job-id', '190', '--raw', '--subdir', 'DAGS_FOLDER/correction.py', '--cfg-path', '/tmp/tmpy1418imf']
[2023-07-11T13:51:19.249+0000] {standard_task_runner.py:85} INFO - Job 190: Subtask save_data
[2023-07-11T13:51:19.480+0000] {task_command.py:410} INFO - Running <TaskInstance: exercice_1.save_data scheduled__2023-07-01T00:00:00+00:00 [running]> on host 1d6232dcfa4d
[2023-07-11T13:51:19.828+0000] {taskinstance.py:1547} INFO - Exporting env vars: AIRFLOW_CTX_DAG_OWNER='***' AIRFLOW_CTX_DAG_ID='exercice_1' AIRFLOW_CTX_TASK_ID='save_data' AIRFLOW_CTX_EXECUTION_DATE='2023-07-01T00:00:00+00:00' AIRFLOW_CTX_TRY_NUMBER='1' AIRFLOW_CTX_DAG_RUN_ID='scheduled__2023-07-01T00:00:00+00:00'
[2023-07-11T13:51:19.881+0000] {taskinstance.py:1824} ERROR - Task failed with exception
Traceback (most recent call last):
  File "/home/airflow/.local/lib/python3.7/site-packages/airflow/operators/python.py", line 181, in execute
    return_value = self.execute_callable()
  File "/home/airflow/.local/lib/python3.7/site-packages/airflow/operators/python.py", line 198, in execute_callable
    return self.python_callable(*self.op_args, **self.op_kwargs)
  File "/opt/airflow/dags/correction.py", line 11, in save_inFile
    .format(context["execution_date"], nb_random())
NameError: name 'nb_random' is not defined
[2023-07-11T13:51:19.940+0000] {taskinstance.py:1350} INFO - Marking task as UP_FOR_RETRY. dag_id=exercice_1, task_id=save_data, execution_date=20230701T000000, start_date=20230711T135119, end_date=20230711T135119
[2023-07-11T13:51:20.025+0000] {standard_task_runner.py:109} ERROR - Failed to execute job 190 for task save_data (name 'nb_random' is not defined; 6840)
[2023-07-11T13:51:20.070+0000] {local_task_job_runner.py:225} INFO - Task exited with return code 1
[2023-07-11T13:51:20.146+0000] {taskinstance.py:2653} INFO - 0 downstream tasks scheduled from follow-on schedule check
[2023-07-11T13:53:40.268+0000] {taskinstance.py:1103} INFO - Dependencies all met for dep_context=non-requeueable deps ti=<TaskInstance: exercice_1.save_data scheduled__2023-07-01T00:00:00+00:00 [queued]>
[2023-07-11T13:53:40.296+0000] {taskinstance.py:1103} INFO - Dependencies all met for dep_context=requeueable deps ti=<TaskInstance: exercice_1.save_data scheduled__2023-07-01T00:00:00+00:00 [queued]>
[2023-07-11T13:53:40.303+0000] {taskinstance.py:1308} INFO - Starting attempt 1 of 2
[2023-07-11T13:53:40.340+0000] {taskinstance.py:1327} INFO - Executing <Task(PythonOperator): save_data> on 2023-07-01 00:00:00+00:00
[2023-07-11T13:53:40.353+0000] {standard_task_runner.py:57} INFO - Started process 6957 to run task
[2023-07-11T13:53:40.374+0000] {standard_task_runner.py:84} INFO - Running: ['***', 'tasks', 'run', 'exercice_1', 'save_data', 'scheduled__2023-07-01T00:00:00+00:00', '--job-id', '213', '--raw', '--subdir', 'DAGS_FOLDER/correction.py', '--cfg-path', '/tmp/tmp178is8cl']
[2023-07-11T13:53:40.380+0000] {standard_task_runner.py:85} INFO - Job 213: Subtask save_data
[2023-07-11T13:53:40.537+0000] {task_command.py:410} INFO - Running <TaskInstance: exercice_1.save_data scheduled__2023-07-01T00:00:00+00:00 [running]> on host 1d6232dcfa4d
[2023-07-11T13:53:40.716+0000] {taskinstance.py:1547} INFO - Exporting env vars: AIRFLOW_CTX_DAG_OWNER='***' AIRFLOW_CTX_DAG_ID='exercice_1' AIRFLOW_CTX_TASK_ID='save_data' AIRFLOW_CTX_EXECUTION_DATE='2023-07-01T00:00:00+00:00' AIRFLOW_CTX_TRY_NUMBER='1' AIRFLOW_CTX_DAG_RUN_ID='scheduled__2023-07-01T00:00:00+00:00'
[2023-07-11T13:53:40.733+0000] {warnings.py:110} WARNING - /home/***/.local/lib/python3.7/site-packages/***/utils/context.py:313: AirflowContextDeprecationWarning: Accessing 'execution_date' from the template is deprecated and will be removed in a future version. Please use 'data_interval_start' or 'logical_date' instead.
  warnings.warn(_create_deprecation_warning(k, replacements))

[2023-07-11T13:53:40.736+0000] {python.py:183} INFO - Done. Returned value was: None
[2023-07-11T13:53:40.770+0000] {taskinstance.py:1350} INFO - Marking task as SUCCESS. dag_id=exercice_1, task_id=save_data, execution_date=20230701T000000, start_date=20230711T135340, end_date=20230711T135340
[2023-07-11T13:53:40.842+0000] {local_task_job_runner.py:225} INFO - Task exited with return code 0
[2023-07-11T13:53:40.877+0000] {taskinstance.py:2653} INFO - 0 downstream tasks scheduled from follow-on schedule check
