[2023-07-11T13:39:23.224+0000] {taskinstance.py:1103} INFO - Dependencies all met for dep_context=non-requeueable deps ti=<TaskInstance: exercice_1.save_data scheduled__2023-07-08T00:00:00+00:00 [queued]>
[2023-07-11T13:39:23.265+0000] {taskinstance.py:1103} INFO - Dependencies all met for dep_context=requeueable deps ti=<TaskInstance: exercice_1.save_data scheduled__2023-07-08T00:00:00+00:00 [queued]>
[2023-07-11T13:39:23.267+0000] {taskinstance.py:1308} INFO - Starting attempt 1 of 2
[2023-07-11T13:39:23.314+0000] {taskinstance.py:1327} INFO - Executing <Task(PythonOperator): save_data> on 2023-07-08 00:00:00+00:00
[2023-07-11T13:39:23.336+0000] {standard_task_runner.py:57} INFO - Started process 6403 to run task
[2023-07-11T13:39:23.354+0000] {standard_task_runner.py:84} INFO - Running: ['***', 'tasks', 'run', 'exercice_1', 'save_data', 'scheduled__2023-07-08T00:00:00+00:00', '--job-id', '127', '--raw', '--subdir', 'DAGS_FOLDER/correction.py', '--cfg-path', '/tmp/tmpqc1cg3_f']
[2023-07-11T13:39:23.362+0000] {standard_task_runner.py:85} INFO - Job 127: Subtask save_data
[2023-07-11T13:39:23.575+0000] {task_command.py:410} INFO - Running <TaskInstance: exercice_1.save_data scheduled__2023-07-08T00:00:00+00:00 [running]> on host 1d6232dcfa4d
[2023-07-11T13:39:23.903+0000] {taskinstance.py:1547} INFO - Exporting env vars: AIRFLOW_CTX_DAG_OWNER='***' AIRFLOW_CTX_DAG_ID='exercice_1' AIRFLOW_CTX_TASK_ID='save_data' AIRFLOW_CTX_EXECUTION_DATE='2023-07-08T00:00:00+00:00' AIRFLOW_CTX_TRY_NUMBER='1' AIRFLOW_CTX_DAG_RUN_ID='scheduled__2023-07-08T00:00:00+00:00'
[2023-07-11T13:39:23.925+0000] {taskinstance.py:1824} ERROR - Task failed with exception
Traceback (most recent call last):
  File "/home/airflow/.local/lib/python3.7/site-packages/airflow/operators/python.py", line 181, in execute
    return_value = self.execute_callable()
  File "/home/airflow/.local/lib/python3.7/site-packages/airflow/operators/python.py", line 198, in execute_callable
    return self.python_callable(*self.op_args, **self.op_kwargs)
  File "/opt/airflow/dags/correction.py", line 11, in save_inFile
    .format(context["execution_date"], nb_random())
NameError: name 'nb_random' is not defined
[2023-07-11T13:39:23.960+0000] {taskinstance.py:1350} INFO - Marking task as UP_FOR_RETRY. dag_id=exercice_1, task_id=save_data, execution_date=20230708T000000, start_date=20230711T133923, end_date=20230711T133923
[2023-07-11T13:39:23.992+0000] {standard_task_runner.py:109} ERROR - Failed to execute job 127 for task save_data (name 'nb_random' is not defined; 6403)
[2023-07-11T13:39:24.022+0000] {local_task_job_runner.py:225} INFO - Task exited with return code 1
[2023-07-11T13:39:24.174+0000] {taskinstance.py:2653} INFO - 0 downstream tasks scheduled from follow-on schedule check
[2023-07-11T13:42:07.616+0000] {taskinstance.py:1103} INFO - Dependencies all met for dep_context=non-requeueable deps ti=<TaskInstance: exercice_1.save_data scheduled__2023-07-08T00:00:00+00:00 [queued]>
[2023-07-11T13:42:07.632+0000] {taskinstance.py:1103} INFO - Dependencies all met for dep_context=requeueable deps ti=<TaskInstance: exercice_1.save_data scheduled__2023-07-08T00:00:00+00:00 [queued]>
[2023-07-11T13:42:07.633+0000] {taskinstance.py:1308} INFO - Starting attempt 1 of 2
[2023-07-11T13:42:07.659+0000] {taskinstance.py:1327} INFO - Executing <Task(PythonOperator): save_data> on 2023-07-08 00:00:00+00:00
[2023-07-11T13:42:07.669+0000] {standard_task_runner.py:57} INFO - Started process 6541 to run task
[2023-07-11T13:42:07.678+0000] {standard_task_runner.py:84} INFO - Running: ['***', 'tasks', 'run', 'exercice_1', 'save_data', 'scheduled__2023-07-08T00:00:00+00:00', '--job-id', '155', '--raw', '--subdir', 'DAGS_FOLDER/correction.py', '--cfg-path', '/tmp/tmpccq_h669']
[2023-07-11T13:42:07.682+0000] {standard_task_runner.py:85} INFO - Job 155: Subtask save_data
[2023-07-11T13:42:07.754+0000] {task_command.py:410} INFO - Running <TaskInstance: exercice_1.save_data scheduled__2023-07-08T00:00:00+00:00 [running]> on host 1d6232dcfa4d
[2023-07-11T13:42:07.879+0000] {taskinstance.py:1547} INFO - Exporting env vars: AIRFLOW_CTX_DAG_OWNER='***' AIRFLOW_CTX_DAG_ID='exercice_1' AIRFLOW_CTX_TASK_ID='save_data' AIRFLOW_CTX_EXECUTION_DATE='2023-07-08T00:00:00+00:00' AIRFLOW_CTX_TRY_NUMBER='1' AIRFLOW_CTX_DAG_RUN_ID='scheduled__2023-07-08T00:00:00+00:00'
[2023-07-11T13:42:07.886+0000] {taskinstance.py:1824} ERROR - Task failed with exception
Traceback (most recent call last):
  File "/home/airflow/.local/lib/python3.7/site-packages/airflow/operators/python.py", line 181, in execute
    return_value = self.execute_callable()
  File "/home/airflow/.local/lib/python3.7/site-packages/airflow/operators/python.py", line 198, in execute_callable
    return self.python_callable(*self.op_args, **self.op_kwargs)
  File "/opt/airflow/dags/correction.py", line 11, in save_inFile
    .format(context["execution_date"], nb_random())
NameError: name 'nb_random' is not defined
[2023-07-11T13:42:07.905+0000] {taskinstance.py:1350} INFO - Marking task as UP_FOR_RETRY. dag_id=exercice_1, task_id=save_data, execution_date=20230708T000000, start_date=20230711T134207, end_date=20230711T134207
[2023-07-11T13:42:07.924+0000] {standard_task_runner.py:109} ERROR - Failed to execute job 155 for task save_data (name 'nb_random' is not defined; 6541)
[2023-07-11T13:42:07.968+0000] {local_task_job_runner.py:225} INFO - Task exited with return code 1
[2023-07-11T13:42:08.024+0000] {taskinstance.py:2653} INFO - 0 downstream tasks scheduled from follow-on schedule check
[2023-07-11T13:48:23.381+0000] {taskinstance.py:1103} INFO - Dependencies all met for dep_context=non-requeueable deps ti=<TaskInstance: exercice_1.save_data scheduled__2023-07-08T00:00:00+00:00 [queued]>
[2023-07-11T13:48:23.401+0000] {taskinstance.py:1103} INFO - Dependencies all met for dep_context=requeueable deps ti=<TaskInstance: exercice_1.save_data scheduled__2023-07-08T00:00:00+00:00 [queued]>
[2023-07-11T13:48:23.402+0000] {taskinstance.py:1308} INFO - Starting attempt 1 of 2
[2023-07-11T13:48:23.447+0000] {taskinstance.py:1327} INFO - Executing <Task(PythonOperator): save_data> on 2023-07-08 00:00:00+00:00
[2023-07-11T13:48:23.458+0000] {standard_task_runner.py:57} INFO - Started process 6728 to run task
[2023-07-11T13:48:23.467+0000] {standard_task_runner.py:84} INFO - Running: ['***', 'tasks', 'run', 'exercice_1', 'save_data', 'scheduled__2023-07-08T00:00:00+00:00', '--job-id', '177', '--raw', '--subdir', 'DAGS_FOLDER/correction.py', '--cfg-path', '/tmp/tmpc_bb1_kt']
[2023-07-11T13:48:23.471+0000] {standard_task_runner.py:85} INFO - Job 177: Subtask save_data
[2023-07-11T13:48:23.554+0000] {task_command.py:410} INFO - Running <TaskInstance: exercice_1.save_data scheduled__2023-07-08T00:00:00+00:00 [running]> on host 1d6232dcfa4d
[2023-07-11T13:48:23.677+0000] {taskinstance.py:1547} INFO - Exporting env vars: AIRFLOW_CTX_DAG_OWNER='***' AIRFLOW_CTX_DAG_ID='exercice_1' AIRFLOW_CTX_TASK_ID='save_data' AIRFLOW_CTX_EXECUTION_DATE='2023-07-08T00:00:00+00:00' AIRFLOW_CTX_TRY_NUMBER='1' AIRFLOW_CTX_DAG_RUN_ID='scheduled__2023-07-08T00:00:00+00:00'
[2023-07-11T13:48:23.683+0000] {taskinstance.py:1824} ERROR - Task failed with exception
Traceback (most recent call last):
  File "/home/airflow/.local/lib/python3.7/site-packages/airflow/operators/python.py", line 181, in execute
    return_value = self.execute_callable()
  File "/home/airflow/.local/lib/python3.7/site-packages/airflow/operators/python.py", line 198, in execute_callable
    return self.python_callable(*self.op_args, **self.op_kwargs)
  File "/opt/airflow/dags/correction.py", line 11, in save_inFile
    .format(context["execution_date"], nb_random())
NameError: name 'nb_random' is not defined
[2023-07-11T13:48:23.702+0000] {taskinstance.py:1350} INFO - Marking task as UP_FOR_RETRY. dag_id=exercice_1, task_id=save_data, execution_date=20230708T000000, start_date=20230711T134823, end_date=20230711T134823
[2023-07-11T13:48:23.718+0000] {standard_task_runner.py:109} ERROR - Failed to execute job 177 for task save_data (name 'nb_random' is not defined; 6728)
[2023-07-11T13:48:23.755+0000] {local_task_job_runner.py:225} INFO - Task exited with return code 1
[2023-07-11T13:48:23.783+0000] {taskinstance.py:2653} INFO - 0 downstream tasks scheduled from follow-on schedule check
[2023-07-11T13:51:22.424+0000] {taskinstance.py:1103} INFO - Dependencies all met for dep_context=non-requeueable deps ti=<TaskInstance: exercice_1.save_data scheduled__2023-07-08T00:00:00+00:00 [queued]>
[2023-07-11T13:51:22.438+0000] {taskinstance.py:1103} INFO - Dependencies all met for dep_context=requeueable deps ti=<TaskInstance: exercice_1.save_data scheduled__2023-07-08T00:00:00+00:00 [queued]>
[2023-07-11T13:51:22.439+0000] {taskinstance.py:1308} INFO - Starting attempt 1 of 2
[2023-07-11T13:51:22.462+0000] {taskinstance.py:1327} INFO - Executing <Task(PythonOperator): save_data> on 2023-07-08 00:00:00+00:00
[2023-07-11T13:51:22.470+0000] {standard_task_runner.py:57} INFO - Started process 6859 to run task
[2023-07-11T13:51:22.476+0000] {standard_task_runner.py:84} INFO - Running: ['***', 'tasks', 'run', 'exercice_1', 'save_data', 'scheduled__2023-07-08T00:00:00+00:00', '--job-id', '199', '--raw', '--subdir', 'DAGS_FOLDER/correction.py', '--cfg-path', '/tmp/tmpk1pcwq7t']
[2023-07-11T13:51:22.479+0000] {standard_task_runner.py:85} INFO - Job 199: Subtask save_data
[2023-07-11T13:51:22.554+0000] {task_command.py:410} INFO - Running <TaskInstance: exercice_1.save_data scheduled__2023-07-08T00:00:00+00:00 [running]> on host 1d6232dcfa4d
[2023-07-11T13:51:22.683+0000] {taskinstance.py:1547} INFO - Exporting env vars: AIRFLOW_CTX_DAG_OWNER='***' AIRFLOW_CTX_DAG_ID='exercice_1' AIRFLOW_CTX_TASK_ID='save_data' AIRFLOW_CTX_EXECUTION_DATE='2023-07-08T00:00:00+00:00' AIRFLOW_CTX_TRY_NUMBER='1' AIRFLOW_CTX_DAG_RUN_ID='scheduled__2023-07-08T00:00:00+00:00'
[2023-07-11T13:51:22.691+0000] {taskinstance.py:1824} ERROR - Task failed with exception
Traceback (most recent call last):
  File "/home/airflow/.local/lib/python3.7/site-packages/airflow/operators/python.py", line 181, in execute
    return_value = self.execute_callable()
  File "/home/airflow/.local/lib/python3.7/site-packages/airflow/operators/python.py", line 198, in execute_callable
    return self.python_callable(*self.op_args, **self.op_kwargs)
  File "/opt/airflow/dags/correction.py", line 11, in save_inFile
    .format(context["execution_date"], nb_random())
NameError: name 'nb_random' is not defined
[2023-07-11T13:51:22.711+0000] {taskinstance.py:1350} INFO - Marking task as UP_FOR_RETRY. dag_id=exercice_1, task_id=save_data, execution_date=20230708T000000, start_date=20230711T135122, end_date=20230711T135122
[2023-07-11T13:51:22.726+0000] {standard_task_runner.py:109} ERROR - Failed to execute job 199 for task save_data (name 'nb_random' is not defined; 6859)
[2023-07-11T13:51:22.767+0000] {local_task_job_runner.py:225} INFO - Task exited with return code 1
[2023-07-11T13:51:22.897+0000] {taskinstance.py:2653} INFO - 0 downstream tasks scheduled from follow-on schedule check
[2023-07-11T13:53:43.170+0000] {taskinstance.py:1103} INFO - Dependencies all met for dep_context=non-requeueable deps ti=<TaskInstance: exercice_1.save_data scheduled__2023-07-08T00:00:00+00:00 [queued]>
[2023-07-11T13:53:43.185+0000] {taskinstance.py:1103} INFO - Dependencies all met for dep_context=requeueable deps ti=<TaskInstance: exercice_1.save_data scheduled__2023-07-08T00:00:00+00:00 [queued]>
[2023-07-11T13:53:43.185+0000] {taskinstance.py:1308} INFO - Starting attempt 1 of 2
[2023-07-11T13:53:43.206+0000] {taskinstance.py:1327} INFO - Executing <Task(PythonOperator): save_data> on 2023-07-08 00:00:00+00:00
[2023-07-11T13:53:43.215+0000] {standard_task_runner.py:57} INFO - Started process 6974 to run task
[2023-07-11T13:53:43.220+0000] {standard_task_runner.py:84} INFO - Running: ['***', 'tasks', 'run', 'exercice_1', 'save_data', 'scheduled__2023-07-08T00:00:00+00:00', '--job-id', '223', '--raw', '--subdir', 'DAGS_FOLDER/correction.py', '--cfg-path', '/tmp/tmp1iy8_gxy']
[2023-07-11T13:53:43.242+0000] {standard_task_runner.py:85} INFO - Job 223: Subtask save_data
[2023-07-11T13:53:43.318+0000] {task_command.py:410} INFO - Running <TaskInstance: exercice_1.save_data scheduled__2023-07-08T00:00:00+00:00 [running]> on host 1d6232dcfa4d
[2023-07-11T13:53:43.441+0000] {taskinstance.py:1547} INFO - Exporting env vars: AIRFLOW_CTX_DAG_OWNER='***' AIRFLOW_CTX_DAG_ID='exercice_1' AIRFLOW_CTX_TASK_ID='save_data' AIRFLOW_CTX_EXECUTION_DATE='2023-07-08T00:00:00+00:00' AIRFLOW_CTX_TRY_NUMBER='1' AIRFLOW_CTX_DAG_RUN_ID='scheduled__2023-07-08T00:00:00+00:00'
[2023-07-11T13:53:43.445+0000] {warnings.py:110} WARNING - /home/***/.local/lib/python3.7/site-packages/***/utils/context.py:313: AirflowContextDeprecationWarning: Accessing 'execution_date' from the template is deprecated and will be removed in a future version. Please use 'data_interval_start' or 'logical_date' instead.
  warnings.warn(_create_deprecation_warning(k, replacements))

[2023-07-11T13:53:43.447+0000] {python.py:183} INFO - Done. Returned value was: None
[2023-07-11T13:53:43.460+0000] {taskinstance.py:1350} INFO - Marking task as SUCCESS. dag_id=exercice_1, task_id=save_data, execution_date=20230708T000000, start_date=20230711T135343, end_date=20230711T135343
[2023-07-11T13:53:43.512+0000] {local_task_job_runner.py:225} INFO - Task exited with return code 0
[2023-07-11T13:53:43.537+0000] {taskinstance.py:2653} INFO - 0 downstream tasks scheduled from follow-on schedule check
