[2023-07-11T13:39:22.717+0000] {taskinstance.py:1103} INFO - Dependencies all met for dep_context=non-requeueable deps ti=<TaskInstance: exercice_1.save_data scheduled__2023-07-03T00:00:00+00:00 [queued]>
[2023-07-11T13:39:22.761+0000] {taskinstance.py:1103} INFO - Dependencies all met for dep_context=requeueable deps ti=<TaskInstance: exercice_1.save_data scheduled__2023-07-03T00:00:00+00:00 [queued]>
[2023-07-11T13:39:22.768+0000] {taskinstance.py:1308} INFO - Starting attempt 1 of 2
[2023-07-11T13:39:22.848+0000] {taskinstance.py:1327} INFO - Executing <Task(PythonOperator): save_data> on 2023-07-03 00:00:00+00:00
[2023-07-11T13:39:22.859+0000] {standard_task_runner.py:57} INFO - Started process 6397 to run task
[2023-07-11T13:39:22.881+0000] {standard_task_runner.py:84} INFO - Running: ['***', 'tasks', 'run', 'exercice_1', 'save_data', 'scheduled__2023-07-03T00:00:00+00:00', '--job-id', '123', '--raw', '--subdir', 'DAGS_FOLDER/correction.py', '--cfg-path', '/tmp/tmp7kiv7i9z']
[2023-07-11T13:39:22.901+0000] {standard_task_runner.py:85} INFO - Job 123: Subtask save_data
[2023-07-11T13:39:23.170+0000] {task_command.py:410} INFO - Running <TaskInstance: exercice_1.save_data scheduled__2023-07-03T00:00:00+00:00 [running]> on host 1d6232dcfa4d
[2023-07-11T13:39:23.496+0000] {taskinstance.py:1547} INFO - Exporting env vars: AIRFLOW_CTX_DAG_OWNER='***' AIRFLOW_CTX_DAG_ID='exercice_1' AIRFLOW_CTX_TASK_ID='save_data' AIRFLOW_CTX_EXECUTION_DATE='2023-07-03T00:00:00+00:00' AIRFLOW_CTX_TRY_NUMBER='1' AIRFLOW_CTX_DAG_RUN_ID='scheduled__2023-07-03T00:00:00+00:00'
[2023-07-11T13:39:23.533+0000] {taskinstance.py:1824} ERROR - Task failed with exception
Traceback (most recent call last):
  File "/home/airflow/.local/lib/python3.7/site-packages/airflow/operators/python.py", line 181, in execute
    return_value = self.execute_callable()
  File "/home/airflow/.local/lib/python3.7/site-packages/airflow/operators/python.py", line 198, in execute_callable
    return self.python_callable(*self.op_args, **self.op_kwargs)
  File "/opt/airflow/dags/correction.py", line 11, in save_inFile
    .format(context["execution_date"], nb_random())
NameError: name 'nb_random' is not defined
[2023-07-11T13:39:23.596+0000] {taskinstance.py:1350} INFO - Marking task as UP_FOR_RETRY. dag_id=exercice_1, task_id=save_data, execution_date=20230703T000000, start_date=20230711T133922, end_date=20230711T133923
[2023-07-11T13:39:23.642+0000] {standard_task_runner.py:109} ERROR - Failed to execute job 123 for task save_data (name 'nb_random' is not defined; 6397)
[2023-07-11T13:39:23.684+0000] {local_task_job_runner.py:225} INFO - Task exited with return code 1
[2023-07-11T13:39:23.755+0000] {taskinstance.py:2653} INFO - 0 downstream tasks scheduled from follow-on schedule check
[2023-07-11T13:42:05.000+0000] {taskinstance.py:1103} INFO - Dependencies all met for dep_context=non-requeueable deps ti=<TaskInstance: exercice_1.save_data scheduled__2023-07-03T00:00:00+00:00 [queued]>
[2023-07-11T13:42:05.033+0000] {taskinstance.py:1103} INFO - Dependencies all met for dep_context=requeueable deps ti=<TaskInstance: exercice_1.save_data scheduled__2023-07-03T00:00:00+00:00 [queued]>
[2023-07-11T13:42:05.034+0000] {taskinstance.py:1308} INFO - Starting attempt 1 of 2
[2023-07-11T13:42:05.115+0000] {taskinstance.py:1327} INFO - Executing <Task(PythonOperator): save_data> on 2023-07-03 00:00:00+00:00
[2023-07-11T13:42:05.126+0000] {standard_task_runner.py:57} INFO - Started process 6527 to run task
[2023-07-11T13:42:05.150+0000] {standard_task_runner.py:84} INFO - Running: ['***', 'tasks', 'run', 'exercice_1', 'save_data', 'scheduled__2023-07-03T00:00:00+00:00', '--job-id', '150', '--raw', '--subdir', 'DAGS_FOLDER/correction.py', '--cfg-path', '/tmp/tmpqt925el2']
[2023-07-11T13:42:05.154+0000] {standard_task_runner.py:85} INFO - Job 150: Subtask save_data
[2023-07-11T13:42:05.375+0000] {task_command.py:410} INFO - Running <TaskInstance: exercice_1.save_data scheduled__2023-07-03T00:00:00+00:00 [running]> on host 1d6232dcfa4d
[2023-07-11T13:42:05.712+0000] {taskinstance.py:1547} INFO - Exporting env vars: AIRFLOW_CTX_DAG_OWNER='***' AIRFLOW_CTX_DAG_ID='exercice_1' AIRFLOW_CTX_TASK_ID='save_data' AIRFLOW_CTX_EXECUTION_DATE='2023-07-03T00:00:00+00:00' AIRFLOW_CTX_TRY_NUMBER='1' AIRFLOW_CTX_DAG_RUN_ID='scheduled__2023-07-03T00:00:00+00:00'
[2023-07-11T13:42:05.730+0000] {taskinstance.py:1824} ERROR - Task failed with exception
Traceback (most recent call last):
  File "/home/airflow/.local/lib/python3.7/site-packages/airflow/operators/python.py", line 181, in execute
    return_value = self.execute_callable()
  File "/home/airflow/.local/lib/python3.7/site-packages/airflow/operators/python.py", line 198, in execute_callable
    return self.python_callable(*self.op_args, **self.op_kwargs)
  File "/opt/airflow/dags/correction.py", line 11, in save_inFile
    .format(context["execution_date"], nb_random())
NameError: name 'nb_random' is not defined
[2023-07-11T13:42:05.754+0000] {taskinstance.py:1350} INFO - Marking task as UP_FOR_RETRY. dag_id=exercice_1, task_id=save_data, execution_date=20230703T000000, start_date=20230711T134205, end_date=20230711T134205
[2023-07-11T13:42:05.843+0000] {standard_task_runner.py:109} ERROR - Failed to execute job 150 for task save_data (name 'nb_random' is not defined; 6527)
[2023-07-11T13:42:05.894+0000] {local_task_job_runner.py:225} INFO - Task exited with return code 1
[2023-07-11T13:42:05.971+0000] {taskinstance.py:2653} INFO - 0 downstream tasks scheduled from follow-on schedule check
[2023-07-11T13:48:21.616+0000] {taskinstance.py:1103} INFO - Dependencies all met for dep_context=non-requeueable deps ti=<TaskInstance: exercice_1.save_data scheduled__2023-07-03T00:00:00+00:00 [queued]>
[2023-07-11T13:48:21.646+0000] {taskinstance.py:1103} INFO - Dependencies all met for dep_context=requeueable deps ti=<TaskInstance: exercice_1.save_data scheduled__2023-07-03T00:00:00+00:00 [queued]>
[2023-07-11T13:48:21.652+0000] {taskinstance.py:1308} INFO - Starting attempt 1 of 2
[2023-07-11T13:48:21.781+0000] {taskinstance.py:1327} INFO - Executing <Task(PythonOperator): save_data> on 2023-07-03 00:00:00+00:00
[2023-07-11T13:48:21.798+0000] {standard_task_runner.py:57} INFO - Started process 6720 to run task
[2023-07-11T13:48:21.816+0000] {standard_task_runner.py:84} INFO - Running: ['***', 'tasks', 'run', 'exercice_1', 'save_data', 'scheduled__2023-07-03T00:00:00+00:00', '--job-id', '171', '--raw', '--subdir', 'DAGS_FOLDER/correction.py', '--cfg-path', '/tmp/tmpkcs_jcml']
[2023-07-11T13:48:21.821+0000] {standard_task_runner.py:85} INFO - Job 171: Subtask save_data
[2023-07-11T13:48:22.031+0000] {task_command.py:410} INFO - Running <TaskInstance: exercice_1.save_data scheduled__2023-07-03T00:00:00+00:00 [running]> on host 1d6232dcfa4d
[2023-07-11T13:48:22.380+0000] {taskinstance.py:1547} INFO - Exporting env vars: AIRFLOW_CTX_DAG_OWNER='***' AIRFLOW_CTX_DAG_ID='exercice_1' AIRFLOW_CTX_TASK_ID='save_data' AIRFLOW_CTX_EXECUTION_DATE='2023-07-03T00:00:00+00:00' AIRFLOW_CTX_TRY_NUMBER='1' AIRFLOW_CTX_DAG_RUN_ID='scheduled__2023-07-03T00:00:00+00:00'
[2023-07-11T13:48:22.399+0000] {taskinstance.py:1824} ERROR - Task failed with exception
Traceback (most recent call last):
  File "/home/airflow/.local/lib/python3.7/site-packages/airflow/operators/python.py", line 181, in execute
    return_value = self.execute_callable()
  File "/home/airflow/.local/lib/python3.7/site-packages/airflow/operators/python.py", line 198, in execute_callable
    return self.python_callable(*self.op_args, **self.op_kwargs)
  File "/opt/airflow/dags/correction.py", line 11, in save_inFile
    .format(context["execution_date"], nb_random())
NameError: name 'nb_random' is not defined
[2023-07-11T13:48:22.445+0000] {taskinstance.py:1350} INFO - Marking task as UP_FOR_RETRY. dag_id=exercice_1, task_id=save_data, execution_date=20230703T000000, start_date=20230711T134821, end_date=20230711T134822
[2023-07-11T13:48:22.483+0000] {standard_task_runner.py:109} ERROR - Failed to execute job 171 for task save_data (name 'nb_random' is not defined; 6720)
[2023-07-11T13:48:22.561+0000] {local_task_job_runner.py:225} INFO - Task exited with return code 1
[2023-07-11T13:48:22.655+0000] {taskinstance.py:2653} INFO - 0 downstream tasks scheduled from follow-on schedule check
[2023-07-11T13:51:20.952+0000] {taskinstance.py:1103} INFO - Dependencies all met for dep_context=non-requeueable deps ti=<TaskInstance: exercice_1.save_data scheduled__2023-07-03T00:00:00+00:00 [queued]>
[2023-07-11T13:51:20.997+0000] {taskinstance.py:1103} INFO - Dependencies all met for dep_context=requeueable deps ti=<TaskInstance: exercice_1.save_data scheduled__2023-07-03T00:00:00+00:00 [queued]>
[2023-07-11T13:51:20.998+0000] {taskinstance.py:1308} INFO - Starting attempt 1 of 2
[2023-07-11T13:51:21.051+0000] {taskinstance.py:1327} INFO - Executing <Task(PythonOperator): save_data> on 2023-07-03 00:00:00+00:00
[2023-07-11T13:51:21.061+0000] {standard_task_runner.py:57} INFO - Started process 6852 to run task
[2023-07-11T13:51:21.091+0000] {standard_task_runner.py:84} INFO - Running: ['***', 'tasks', 'run', 'exercice_1', 'save_data', 'scheduled__2023-07-03T00:00:00+00:00', '--job-id', '196', '--raw', '--subdir', 'DAGS_FOLDER/correction.py', '--cfg-path', '/tmp/tmp16h9qdc8']
[2023-07-11T13:51:21.109+0000] {standard_task_runner.py:85} INFO - Job 196: Subtask save_data
[2023-07-11T13:51:21.311+0000] {task_command.py:410} INFO - Running <TaskInstance: exercice_1.save_data scheduled__2023-07-03T00:00:00+00:00 [running]> on host 1d6232dcfa4d
[2023-07-11T13:51:21.605+0000] {taskinstance.py:1547} INFO - Exporting env vars: AIRFLOW_CTX_DAG_OWNER='***' AIRFLOW_CTX_DAG_ID='exercice_1' AIRFLOW_CTX_TASK_ID='save_data' AIRFLOW_CTX_EXECUTION_DATE='2023-07-03T00:00:00+00:00' AIRFLOW_CTX_TRY_NUMBER='1' AIRFLOW_CTX_DAG_RUN_ID='scheduled__2023-07-03T00:00:00+00:00'
[2023-07-11T13:51:21.640+0000] {taskinstance.py:1824} ERROR - Task failed with exception
Traceback (most recent call last):
  File "/home/airflow/.local/lib/python3.7/site-packages/airflow/operators/python.py", line 181, in execute
    return_value = self.execute_callable()
  File "/home/airflow/.local/lib/python3.7/site-packages/airflow/operators/python.py", line 198, in execute_callable
    return self.python_callable(*self.op_args, **self.op_kwargs)
  File "/opt/airflow/dags/correction.py", line 11, in save_inFile
    .format(context["execution_date"], nb_random())
NameError: name 'nb_random' is not defined
[2023-07-11T13:51:21.686+0000] {taskinstance.py:1350} INFO - Marking task as UP_FOR_RETRY. dag_id=exercice_1, task_id=save_data, execution_date=20230703T000000, start_date=20230711T135120, end_date=20230711T135121
[2023-07-11T13:51:21.750+0000] {standard_task_runner.py:109} ERROR - Failed to execute job 196 for task save_data (name 'nb_random' is not defined; 6852)
[2023-07-11T13:51:21.878+0000] {local_task_job_runner.py:225} INFO - Task exited with return code 1
[2023-07-11T13:51:21.929+0000] {taskinstance.py:2653} INFO - 0 downstream tasks scheduled from follow-on schedule check
[2023-07-11T13:53:40.837+0000] {taskinstance.py:1103} INFO - Dependencies all met for dep_context=non-requeueable deps ti=<TaskInstance: exercice_1.save_data scheduled__2023-07-03T00:00:00+00:00 [queued]>
[2023-07-11T13:53:40.858+0000] {taskinstance.py:1103} INFO - Dependencies all met for dep_context=requeueable deps ti=<TaskInstance: exercice_1.save_data scheduled__2023-07-03T00:00:00+00:00 [queued]>
[2023-07-11T13:53:40.859+0000] {taskinstance.py:1308} INFO - Starting attempt 1 of 2
[2023-07-11T13:53:40.888+0000] {taskinstance.py:1327} INFO - Executing <Task(PythonOperator): save_data> on 2023-07-03 00:00:00+00:00
[2023-07-11T13:53:40.896+0000] {standard_task_runner.py:57} INFO - Started process 6961 to run task
[2023-07-11T13:53:40.903+0000] {standard_task_runner.py:84} INFO - Running: ['***', 'tasks', 'run', 'exercice_1', 'save_data', 'scheduled__2023-07-03T00:00:00+00:00', '--job-id', '216', '--raw', '--subdir', 'DAGS_FOLDER/correction.py', '--cfg-path', '/tmp/tmpigx23wtt']
[2023-07-11T13:53:40.908+0000] {standard_task_runner.py:85} INFO - Job 216: Subtask save_data
[2023-07-11T13:53:41.032+0000] {task_command.py:410} INFO - Running <TaskInstance: exercice_1.save_data scheduled__2023-07-03T00:00:00+00:00 [running]> on host 1d6232dcfa4d
[2023-07-11T13:53:41.317+0000] {taskinstance.py:1547} INFO - Exporting env vars: AIRFLOW_CTX_DAG_OWNER='***' AIRFLOW_CTX_DAG_ID='exercice_1' AIRFLOW_CTX_TASK_ID='save_data' AIRFLOW_CTX_EXECUTION_DATE='2023-07-03T00:00:00+00:00' AIRFLOW_CTX_TRY_NUMBER='1' AIRFLOW_CTX_DAG_RUN_ID='scheduled__2023-07-03T00:00:00+00:00'
[2023-07-11T13:53:41.354+0000] {warnings.py:110} WARNING - /home/***/.local/lib/python3.7/site-packages/***/utils/context.py:313: AirflowContextDeprecationWarning: Accessing 'execution_date' from the template is deprecated and will be removed in a future version. Please use 'data_interval_start' or 'logical_date' instead.
  warnings.warn(_create_deprecation_warning(k, replacements))

[2023-07-11T13:53:41.380+0000] {python.py:183} INFO - Done. Returned value was: None
[2023-07-11T13:53:41.429+0000] {taskinstance.py:1350} INFO - Marking task as SUCCESS. dag_id=exercice_1, task_id=save_data, execution_date=20230703T000000, start_date=20230711T135340, end_date=20230711T135341
[2023-07-11T13:53:41.501+0000] {local_task_job_runner.py:225} INFO - Task exited with return code 0
[2023-07-11T13:53:41.553+0000] {taskinstance.py:2653} INFO - 0 downstream tasks scheduled from follow-on schedule check
