[2023-07-11T13:39:23.090+0000] {taskinstance.py:1103} INFO - Dependencies all met for dep_context=non-requeueable deps ti=<TaskInstance: exercice_1.save_data scheduled__2023-07-10T00:00:00+00:00 [queued]>
[2023-07-11T13:39:23.136+0000] {taskinstance.py:1103} INFO - Dependencies all met for dep_context=requeueable deps ti=<TaskInstance: exercice_1.save_data scheduled__2023-07-10T00:00:00+00:00 [queued]>
[2023-07-11T13:39:23.139+0000] {taskinstance.py:1308} INFO - Starting attempt 1 of 2
[2023-07-11T13:39:23.198+0000] {taskinstance.py:1327} INFO - Executing <Task(PythonOperator): save_data> on 2023-07-10 00:00:00+00:00
[2023-07-11T13:39:23.209+0000] {standard_task_runner.py:57} INFO - Started process 6402 to run task
[2023-07-11T13:39:23.225+0000] {standard_task_runner.py:84} INFO - Running: ['***', 'tasks', 'run', 'exercice_1', 'save_data', 'scheduled__2023-07-10T00:00:00+00:00', '--job-id', '129', '--raw', '--subdir', 'DAGS_FOLDER/correction.py', '--cfg-path', '/tmp/tmp3ecee0k6']
[2023-07-11T13:39:23.247+0000] {standard_task_runner.py:85} INFO - Job 129: Subtask save_data
[2023-07-11T13:39:23.454+0000] {task_command.py:410} INFO - Running <TaskInstance: exercice_1.save_data scheduled__2023-07-10T00:00:00+00:00 [running]> on host 1d6232dcfa4d
[2023-07-11T13:39:23.763+0000] {taskinstance.py:1547} INFO - Exporting env vars: AIRFLOW_CTX_DAG_OWNER='***' AIRFLOW_CTX_DAG_ID='exercice_1' AIRFLOW_CTX_TASK_ID='save_data' AIRFLOW_CTX_EXECUTION_DATE='2023-07-10T00:00:00+00:00' AIRFLOW_CTX_TRY_NUMBER='1' AIRFLOW_CTX_DAG_RUN_ID='scheduled__2023-07-10T00:00:00+00:00'
[2023-07-11T13:39:23.783+0000] {taskinstance.py:1824} ERROR - Task failed with exception
Traceback (most recent call last):
  File "/home/airflow/.local/lib/python3.7/site-packages/airflow/operators/python.py", line 181, in execute
    return_value = self.execute_callable()
  File "/home/airflow/.local/lib/python3.7/site-packages/airflow/operators/python.py", line 198, in execute_callable
    return self.python_callable(*self.op_args, **self.op_kwargs)
  File "/opt/airflow/dags/correction.py", line 11, in save_inFile
    .format(context["execution_date"], nb_random())
NameError: name 'nb_random' is not defined
[2023-07-11T13:39:23.824+0000] {taskinstance.py:1350} INFO - Marking task as UP_FOR_RETRY. dag_id=exercice_1, task_id=save_data, execution_date=20230710T000000, start_date=20230711T133923, end_date=20230711T133923
[2023-07-11T13:39:23.873+0000] {standard_task_runner.py:109} ERROR - Failed to execute job 129 for task save_data (name 'nb_random' is not defined; 6402)
[2023-07-11T13:39:23.932+0000] {local_task_job_runner.py:225} INFO - Task exited with return code 1
[2023-07-11T13:39:23.979+0000] {taskinstance.py:2653} INFO - 0 downstream tasks scheduled from follow-on schedule check
[2023-07-11T13:42:07.701+0000] {taskinstance.py:1103} INFO - Dependencies all met for dep_context=non-requeueable deps ti=<TaskInstance: exercice_1.save_data scheduled__2023-07-10T00:00:00+00:00 [queued]>
[2023-07-11T13:42:07.714+0000] {taskinstance.py:1103} INFO - Dependencies all met for dep_context=requeueable deps ti=<TaskInstance: exercice_1.save_data scheduled__2023-07-10T00:00:00+00:00 [queued]>
[2023-07-11T13:42:07.715+0000] {taskinstance.py:1308} INFO - Starting attempt 1 of 2
[2023-07-11T13:42:07.737+0000] {taskinstance.py:1327} INFO - Executing <Task(PythonOperator): save_data> on 2023-07-10 00:00:00+00:00
[2023-07-11T13:42:07.745+0000] {standard_task_runner.py:57} INFO - Started process 6543 to run task
[2023-07-11T13:42:07.750+0000] {standard_task_runner.py:84} INFO - Running: ['***', 'tasks', 'run', 'exercice_1', 'save_data', 'scheduled__2023-07-10T00:00:00+00:00', '--job-id', '157', '--raw', '--subdir', 'DAGS_FOLDER/correction.py', '--cfg-path', '/tmp/tmpxtjragbv']
[2023-07-11T13:42:07.755+0000] {standard_task_runner.py:85} INFO - Job 157: Subtask save_data
[2023-07-11T13:42:07.835+0000] {task_command.py:410} INFO - Running <TaskInstance: exercice_1.save_data scheduled__2023-07-10T00:00:00+00:00 [running]> on host 1d6232dcfa4d
[2023-07-11T13:42:07.974+0000] {taskinstance.py:1547} INFO - Exporting env vars: AIRFLOW_CTX_DAG_OWNER='***' AIRFLOW_CTX_DAG_ID='exercice_1' AIRFLOW_CTX_TASK_ID='save_data' AIRFLOW_CTX_EXECUTION_DATE='2023-07-10T00:00:00+00:00' AIRFLOW_CTX_TRY_NUMBER='1' AIRFLOW_CTX_DAG_RUN_ID='scheduled__2023-07-10T00:00:00+00:00'
[2023-07-11T13:42:07.997+0000] {taskinstance.py:1824} ERROR - Task failed with exception
Traceback (most recent call last):
  File "/home/airflow/.local/lib/python3.7/site-packages/airflow/operators/python.py", line 181, in execute
    return_value = self.execute_callable()
  File "/home/airflow/.local/lib/python3.7/site-packages/airflow/operators/python.py", line 198, in execute_callable
    return self.python_callable(*self.op_args, **self.op_kwargs)
  File "/opt/airflow/dags/correction.py", line 11, in save_inFile
    .format(context["execution_date"], nb_random())
NameError: name 'nb_random' is not defined
[2023-07-11T13:42:08.015+0000] {taskinstance.py:1350} INFO - Marking task as UP_FOR_RETRY. dag_id=exercice_1, task_id=save_data, execution_date=20230710T000000, start_date=20230711T134207, end_date=20230711T134208
[2023-07-11T13:42:08.032+0000] {standard_task_runner.py:109} ERROR - Failed to execute job 157 for task save_data (name 'nb_random' is not defined; 6543)
[2023-07-11T13:42:08.051+0000] {local_task_job_runner.py:225} INFO - Task exited with return code 1
[2023-07-11T13:42:08.078+0000] {taskinstance.py:2653} INFO - 0 downstream tasks scheduled from follow-on schedule check
[2023-07-11T13:48:24.145+0000] {taskinstance.py:1103} INFO - Dependencies all met for dep_context=non-requeueable deps ti=<TaskInstance: exercice_1.save_data scheduled__2023-07-10T00:00:00+00:00 [queued]>
[2023-07-11T13:48:24.159+0000] {taskinstance.py:1103} INFO - Dependencies all met for dep_context=requeueable deps ti=<TaskInstance: exercice_1.save_data scheduled__2023-07-10T00:00:00+00:00 [queued]>
[2023-07-11T13:48:24.160+0000] {taskinstance.py:1308} INFO - Starting attempt 1 of 2
[2023-07-11T13:48:24.178+0000] {taskinstance.py:1327} INFO - Executing <Task(PythonOperator): save_data> on 2023-07-10 00:00:00+00:00
[2023-07-11T13:48:24.185+0000] {standard_task_runner.py:57} INFO - Started process 6731 to run task
[2023-07-11T13:48:24.189+0000] {standard_task_runner.py:84} INFO - Running: ['***', 'tasks', 'run', 'exercice_1', 'save_data', 'scheduled__2023-07-10T00:00:00+00:00', '--job-id', '179', '--raw', '--subdir', 'DAGS_FOLDER/correction.py', '--cfg-path', '/tmp/tmprrvr3el3']
[2023-07-11T13:48:24.193+0000] {standard_task_runner.py:85} INFO - Job 179: Subtask save_data
[2023-07-11T13:48:24.254+0000] {task_command.py:410} INFO - Running <TaskInstance: exercice_1.save_data scheduled__2023-07-10T00:00:00+00:00 [running]> on host 1d6232dcfa4d
[2023-07-11T13:48:24.353+0000] {taskinstance.py:1547} INFO - Exporting env vars: AIRFLOW_CTX_DAG_OWNER='***' AIRFLOW_CTX_DAG_ID='exercice_1' AIRFLOW_CTX_TASK_ID='save_data' AIRFLOW_CTX_EXECUTION_DATE='2023-07-10T00:00:00+00:00' AIRFLOW_CTX_TRY_NUMBER='1' AIRFLOW_CTX_DAG_RUN_ID='scheduled__2023-07-10T00:00:00+00:00'
[2023-07-11T13:48:24.360+0000] {taskinstance.py:1824} ERROR - Task failed with exception
Traceback (most recent call last):
  File "/home/airflow/.local/lib/python3.7/site-packages/airflow/operators/python.py", line 181, in execute
    return_value = self.execute_callable()
  File "/home/airflow/.local/lib/python3.7/site-packages/airflow/operators/python.py", line 198, in execute_callable
    return self.python_callable(*self.op_args, **self.op_kwargs)
  File "/opt/airflow/dags/correction.py", line 11, in save_inFile
    .format(context["execution_date"], nb_random())
NameError: name 'nb_random' is not defined
[2023-07-11T13:48:24.378+0000] {taskinstance.py:1350} INFO - Marking task as UP_FOR_RETRY. dag_id=exercice_1, task_id=save_data, execution_date=20230710T000000, start_date=20230711T134824, end_date=20230711T134824
[2023-07-11T13:48:24.392+0000] {standard_task_runner.py:109} ERROR - Failed to execute job 179 for task save_data (name 'nb_random' is not defined; 6731)
[2023-07-11T13:48:24.441+0000] {local_task_job_runner.py:225} INFO - Task exited with return code 1
[2023-07-11T13:48:24.463+0000] {taskinstance.py:2653} INFO - 0 downstream tasks scheduled from follow-on schedule check
[2023-07-11T13:51:23.346+0000] {taskinstance.py:1103} INFO - Dependencies all met for dep_context=non-requeueable deps ti=<TaskInstance: exercice_1.save_data scheduled__2023-07-10T00:00:00+00:00 [queued]>
[2023-07-11T13:51:23.357+0000] {taskinstance.py:1103} INFO - Dependencies all met for dep_context=requeueable deps ti=<TaskInstance: exercice_1.save_data scheduled__2023-07-10T00:00:00+00:00 [queued]>
[2023-07-11T13:51:23.357+0000] {taskinstance.py:1308} INFO - Starting attempt 1 of 2
[2023-07-11T13:51:23.374+0000] {taskinstance.py:1327} INFO - Executing <Task(PythonOperator): save_data> on 2023-07-10 00:00:00+00:00
[2023-07-11T13:51:23.381+0000] {standard_task_runner.py:57} INFO - Started process 6862 to run task
[2023-07-11T13:51:23.385+0000] {standard_task_runner.py:84} INFO - Running: ['***', 'tasks', 'run', 'exercice_1', 'save_data', 'scheduled__2023-07-10T00:00:00+00:00', '--job-id', '201', '--raw', '--subdir', 'DAGS_FOLDER/correction.py', '--cfg-path', '/tmp/tmpe222trn1']
[2023-07-11T13:51:23.389+0000] {standard_task_runner.py:85} INFO - Job 201: Subtask save_data
[2023-07-11T13:51:23.454+0000] {task_command.py:410} INFO - Running <TaskInstance: exercice_1.save_data scheduled__2023-07-10T00:00:00+00:00 [running]> on host 1d6232dcfa4d
[2023-07-11T13:51:23.633+0000] {taskinstance.py:1547} INFO - Exporting env vars: AIRFLOW_CTX_DAG_OWNER='***' AIRFLOW_CTX_DAG_ID='exercice_1' AIRFLOW_CTX_TASK_ID='save_data' AIRFLOW_CTX_EXECUTION_DATE='2023-07-10T00:00:00+00:00' AIRFLOW_CTX_TRY_NUMBER='1' AIRFLOW_CTX_DAG_RUN_ID='scheduled__2023-07-10T00:00:00+00:00'
[2023-07-11T13:51:23.643+0000] {taskinstance.py:1824} ERROR - Task failed with exception
Traceback (most recent call last):
  File "/home/airflow/.local/lib/python3.7/site-packages/airflow/operators/python.py", line 181, in execute
    return_value = self.execute_callable()
  File "/home/airflow/.local/lib/python3.7/site-packages/airflow/operators/python.py", line 198, in execute_callable
    return self.python_callable(*self.op_args, **self.op_kwargs)
  File "/opt/airflow/dags/correction.py", line 11, in save_inFile
    .format(context["execution_date"], nb_random())
NameError: name 'nb_random' is not defined
[2023-07-11T13:51:23.661+0000] {taskinstance.py:1350} INFO - Marking task as UP_FOR_RETRY. dag_id=exercice_1, task_id=save_data, execution_date=20230710T000000, start_date=20230711T135123, end_date=20230711T135123
[2023-07-11T13:51:23.676+0000] {standard_task_runner.py:109} ERROR - Failed to execute job 201 for task save_data (name 'nb_random' is not defined; 6862)
[2023-07-11T13:51:23.717+0000] {local_task_job_runner.py:225} INFO - Task exited with return code 1
[2023-07-11T13:51:23.741+0000] {taskinstance.py:2653} INFO - 0 downstream tasks scheduled from follow-on schedule check
[2023-07-11T13:53:43.096+0000] {taskinstance.py:1103} INFO - Dependencies all met for dep_context=non-requeueable deps ti=<TaskInstance: exercice_1.save_data scheduled__2023-07-10T00:00:00+00:00 [queued]>
[2023-07-11T13:53:43.121+0000] {taskinstance.py:1103} INFO - Dependencies all met for dep_context=requeueable deps ti=<TaskInstance: exercice_1.save_data scheduled__2023-07-10T00:00:00+00:00 [queued]>
[2023-07-11T13:53:43.124+0000] {taskinstance.py:1308} INFO - Starting attempt 1 of 2
[2023-07-11T13:53:43.156+0000] {taskinstance.py:1327} INFO - Executing <Task(PythonOperator): save_data> on 2023-07-10 00:00:00+00:00
[2023-07-11T13:53:43.165+0000] {standard_task_runner.py:57} INFO - Started process 6973 to run task
[2023-07-11T13:53:43.170+0000] {standard_task_runner.py:84} INFO - Running: ['***', 'tasks', 'run', 'exercice_1', 'save_data', 'scheduled__2023-07-10T00:00:00+00:00', '--job-id', '221', '--raw', '--subdir', 'DAGS_FOLDER/correction.py', '--cfg-path', '/tmp/tmpwemktwi3']
[2023-07-11T13:53:43.173+0000] {standard_task_runner.py:85} INFO - Job 221: Subtask save_data
[2023-07-11T13:53:43.254+0000] {task_command.py:410} INFO - Running <TaskInstance: exercice_1.save_data scheduled__2023-07-10T00:00:00+00:00 [running]> on host 1d6232dcfa4d
[2023-07-11T13:53:43.385+0000] {taskinstance.py:1547} INFO - Exporting env vars: AIRFLOW_CTX_DAG_OWNER='***' AIRFLOW_CTX_DAG_ID='exercice_1' AIRFLOW_CTX_TASK_ID='save_data' AIRFLOW_CTX_EXECUTION_DATE='2023-07-10T00:00:00+00:00' AIRFLOW_CTX_TRY_NUMBER='1' AIRFLOW_CTX_DAG_RUN_ID='scheduled__2023-07-10T00:00:00+00:00'
[2023-07-11T13:53:43.391+0000] {warnings.py:110} WARNING - /home/***/.local/lib/python3.7/site-packages/***/utils/context.py:313: AirflowContextDeprecationWarning: Accessing 'execution_date' from the template is deprecated and will be removed in a future version. Please use 'data_interval_start' or 'logical_date' instead.
  warnings.warn(_create_deprecation_warning(k, replacements))

[2023-07-11T13:53:43.394+0000] {python.py:183} INFO - Done. Returned value was: None
[2023-07-11T13:53:43.407+0000] {taskinstance.py:1350} INFO - Marking task as SUCCESS. dag_id=exercice_1, task_id=save_data, execution_date=20230710T000000, start_date=20230711T135343, end_date=20230711T135343
[2023-07-11T13:53:43.462+0000] {local_task_job_runner.py:225} INFO - Task exited with return code 0
[2023-07-11T13:53:43.488+0000] {taskinstance.py:2653} INFO - 0 downstream tasks scheduled from follow-on schedule check
