[2023-07-11T13:39:22.829+0000] {taskinstance.py:1103} INFO - Dependencies all met for dep_context=non-requeueable deps ti=<TaskInstance: exercice_1.save_data scheduled__2023-07-04T00:00:00+00:00 [queued]>
[2023-07-11T13:39:22.852+0000] {taskinstance.py:1103} INFO - Dependencies all met for dep_context=requeueable deps ti=<TaskInstance: exercice_1.save_data scheduled__2023-07-04T00:00:00+00:00 [queued]>
[2023-07-11T13:39:22.853+0000] {taskinstance.py:1308} INFO - Starting attempt 1 of 2
[2023-07-11T13:39:22.906+0000] {taskinstance.py:1327} INFO - Executing <Task(PythonOperator): save_data> on 2023-07-04 00:00:00+00:00
[2023-07-11T13:39:22.956+0000] {standard_task_runner.py:57} INFO - Started process 6399 to run task
[2023-07-11T13:39:22.977+0000] {standard_task_runner.py:84} INFO - Running: ['***', 'tasks', 'run', 'exercice_1', 'save_data', 'scheduled__2023-07-04T00:00:00+00:00', '--job-id', '125', '--raw', '--subdir', 'DAGS_FOLDER/correction.py', '--cfg-path', '/tmp/tmpcs_30xvz']
[2023-07-11T13:39:22.996+0000] {standard_task_runner.py:85} INFO - Job 125: Subtask save_data
[2023-07-11T13:39:23.153+0000] {task_command.py:410} INFO - Running <TaskInstance: exercice_1.save_data scheduled__2023-07-04T00:00:00+00:00 [running]> on host 1d6232dcfa4d
[2023-07-11T13:39:23.542+0000] {taskinstance.py:1547} INFO - Exporting env vars: AIRFLOW_CTX_DAG_OWNER='***' AIRFLOW_CTX_DAG_ID='exercice_1' AIRFLOW_CTX_TASK_ID='save_data' AIRFLOW_CTX_EXECUTION_DATE='2023-07-04T00:00:00+00:00' AIRFLOW_CTX_TRY_NUMBER='1' AIRFLOW_CTX_DAG_RUN_ID='scheduled__2023-07-04T00:00:00+00:00'
[2023-07-11T13:39:23.558+0000] {taskinstance.py:1824} ERROR - Task failed with exception
Traceback (most recent call last):
  File "/home/airflow/.local/lib/python3.7/site-packages/airflow/operators/python.py", line 181, in execute
    return_value = self.execute_callable()
  File "/home/airflow/.local/lib/python3.7/site-packages/airflow/operators/python.py", line 198, in execute_callable
    return self.python_callable(*self.op_args, **self.op_kwargs)
  File "/opt/airflow/dags/correction.py", line 11, in save_inFile
    .format(context["execution_date"], nb_random())
NameError: name 'nb_random' is not defined
[2023-07-11T13:39:23.621+0000] {taskinstance.py:1350} INFO - Marking task as UP_FOR_RETRY. dag_id=exercice_1, task_id=save_data, execution_date=20230704T000000, start_date=20230711T133922, end_date=20230711T133923
[2023-07-11T13:39:23.649+0000] {standard_task_runner.py:109} ERROR - Failed to execute job 125 for task save_data (name 'nb_random' is not defined; 6399)
[2023-07-11T13:39:23.697+0000] {local_task_job_runner.py:225} INFO - Task exited with return code 1
[2023-07-11T13:39:23.768+0000] {taskinstance.py:2653} INFO - 0 downstream tasks scheduled from follow-on schedule check
[2023-07-11T13:42:05.587+0000] {taskinstance.py:1103} INFO - Dependencies all met for dep_context=non-requeueable deps ti=<TaskInstance: exercice_1.save_data scheduled__2023-07-04T00:00:00+00:00 [queued]>
[2023-07-11T13:42:05.632+0000] {taskinstance.py:1103} INFO - Dependencies all met for dep_context=requeueable deps ti=<TaskInstance: exercice_1.save_data scheduled__2023-07-04T00:00:00+00:00 [queued]>
[2023-07-11T13:42:05.633+0000] {taskinstance.py:1308} INFO - Starting attempt 1 of 2
[2023-07-11T13:42:05.704+0000] {taskinstance.py:1327} INFO - Executing <Task(PythonOperator): save_data> on 2023-07-04 00:00:00+00:00
[2023-07-11T13:42:05.720+0000] {standard_task_runner.py:57} INFO - Started process 6533 to run task
[2023-07-11T13:42:05.744+0000] {standard_task_runner.py:84} INFO - Running: ['***', 'tasks', 'run', 'exercice_1', 'save_data', 'scheduled__2023-07-04T00:00:00+00:00', '--job-id', '151', '--raw', '--subdir', 'DAGS_FOLDER/correction.py', '--cfg-path', '/tmp/tmp0zdlcmk3']
[2023-07-11T13:42:05.764+0000] {standard_task_runner.py:85} INFO - Job 151: Subtask save_data
[2023-07-11T13:42:06.051+0000] {task_command.py:410} INFO - Running <TaskInstance: exercice_1.save_data scheduled__2023-07-04T00:00:00+00:00 [running]> on host 1d6232dcfa4d
[2023-07-11T13:42:06.287+0000] {taskinstance.py:1547} INFO - Exporting env vars: AIRFLOW_CTX_DAG_OWNER='***' AIRFLOW_CTX_DAG_ID='exercice_1' AIRFLOW_CTX_TASK_ID='save_data' AIRFLOW_CTX_EXECUTION_DATE='2023-07-04T00:00:00+00:00' AIRFLOW_CTX_TRY_NUMBER='1' AIRFLOW_CTX_DAG_RUN_ID='scheduled__2023-07-04T00:00:00+00:00'
[2023-07-11T13:42:06.303+0000] {taskinstance.py:1824} ERROR - Task failed with exception
Traceback (most recent call last):
  File "/home/airflow/.local/lib/python3.7/site-packages/airflow/operators/python.py", line 181, in execute
    return_value = self.execute_callable()
  File "/home/airflow/.local/lib/python3.7/site-packages/airflow/operators/python.py", line 198, in execute_callable
    return self.python_callable(*self.op_args, **self.op_kwargs)
  File "/opt/airflow/dags/correction.py", line 11, in save_inFile
    .format(context["execution_date"], nb_random())
NameError: name 'nb_random' is not defined
[2023-07-11T13:42:06.339+0000] {taskinstance.py:1350} INFO - Marking task as UP_FOR_RETRY. dag_id=exercice_1, task_id=save_data, execution_date=20230704T000000, start_date=20230711T134205, end_date=20230711T134206
[2023-07-11T13:42:06.365+0000] {standard_task_runner.py:109} ERROR - Failed to execute job 151 for task save_data (name 'nb_random' is not defined; 6533)
[2023-07-11T13:42:06.429+0000] {local_task_job_runner.py:225} INFO - Task exited with return code 1
[2023-07-11T13:42:06.472+0000] {taskinstance.py:2653} INFO - 0 downstream tasks scheduled from follow-on schedule check
[2023-07-11T13:48:21.723+0000] {taskinstance.py:1103} INFO - Dependencies all met for dep_context=non-requeueable deps ti=<TaskInstance: exercice_1.save_data scheduled__2023-07-04T00:00:00+00:00 [queued]>
[2023-07-11T13:48:21.746+0000] {taskinstance.py:1103} INFO - Dependencies all met for dep_context=requeueable deps ti=<TaskInstance: exercice_1.save_data scheduled__2023-07-04T00:00:00+00:00 [queued]>
[2023-07-11T13:48:21.747+0000] {taskinstance.py:1308} INFO - Starting attempt 1 of 2
[2023-07-11T13:48:21.828+0000] {taskinstance.py:1327} INFO - Executing <Task(PythonOperator): save_data> on 2023-07-04 00:00:00+00:00
[2023-07-11T13:48:21.841+0000] {standard_task_runner.py:57} INFO - Started process 6721 to run task
[2023-07-11T13:48:21.858+0000] {standard_task_runner.py:84} INFO - Running: ['***', 'tasks', 'run', 'exercice_1', 'save_data', 'scheduled__2023-07-04T00:00:00+00:00', '--job-id', '172', '--raw', '--subdir', 'DAGS_FOLDER/correction.py', '--cfg-path', '/tmp/tmpn3grg1xw']
[2023-07-11T13:48:21.874+0000] {standard_task_runner.py:85} INFO - Job 172: Subtask save_data
[2023-07-11T13:48:22.102+0000] {task_command.py:410} INFO - Running <TaskInstance: exercice_1.save_data scheduled__2023-07-04T00:00:00+00:00 [running]> on host 1d6232dcfa4d
[2023-07-11T13:48:22.347+0000] {taskinstance.py:1547} INFO - Exporting env vars: AIRFLOW_CTX_DAG_OWNER='***' AIRFLOW_CTX_DAG_ID='exercice_1' AIRFLOW_CTX_TASK_ID='save_data' AIRFLOW_CTX_EXECUTION_DATE='2023-07-04T00:00:00+00:00' AIRFLOW_CTX_TRY_NUMBER='1' AIRFLOW_CTX_DAG_RUN_ID='scheduled__2023-07-04T00:00:00+00:00'
[2023-07-11T13:48:22.392+0000] {taskinstance.py:1824} ERROR - Task failed with exception
Traceback (most recent call last):
  File "/home/airflow/.local/lib/python3.7/site-packages/airflow/operators/python.py", line 181, in execute
    return_value = self.execute_callable()
  File "/home/airflow/.local/lib/python3.7/site-packages/airflow/operators/python.py", line 198, in execute_callable
    return self.python_callable(*self.op_args, **self.op_kwargs)
  File "/opt/airflow/dags/correction.py", line 11, in save_inFile
    .format(context["execution_date"], nb_random())
NameError: name 'nb_random' is not defined
[2023-07-11T13:48:22.471+0000] {taskinstance.py:1350} INFO - Marking task as UP_FOR_RETRY. dag_id=exercice_1, task_id=save_data, execution_date=20230704T000000, start_date=20230711T134821, end_date=20230711T134822
[2023-07-11T13:48:22.501+0000] {standard_task_runner.py:109} ERROR - Failed to execute job 172 for task save_data (name 'nb_random' is not defined; 6721)
[2023-07-11T13:48:22.581+0000] {local_task_job_runner.py:225} INFO - Task exited with return code 1
[2023-07-11T13:48:22.750+0000] {taskinstance.py:2653} INFO - 0 downstream tasks scheduled from follow-on schedule check
[2023-07-11T13:51:20.896+0000] {taskinstance.py:1103} INFO - Dependencies all met for dep_context=non-requeueable deps ti=<TaskInstance: exercice_1.save_data scheduled__2023-07-04T00:00:00+00:00 [queued]>
[2023-07-11T13:51:20.929+0000] {taskinstance.py:1103} INFO - Dependencies all met for dep_context=requeueable deps ti=<TaskInstance: exercice_1.save_data scheduled__2023-07-04T00:00:00+00:00 [queued]>
[2023-07-11T13:51:20.930+0000] {taskinstance.py:1308} INFO - Starting attempt 1 of 2
[2023-07-11T13:51:21.022+0000] {taskinstance.py:1327} INFO - Executing <Task(PythonOperator): save_data> on 2023-07-04 00:00:00+00:00
[2023-07-11T13:51:21.034+0000] {standard_task_runner.py:57} INFO - Started process 6851 to run task
[2023-07-11T13:51:21.050+0000] {standard_task_runner.py:84} INFO - Running: ['***', 'tasks', 'run', 'exercice_1', 'save_data', 'scheduled__2023-07-04T00:00:00+00:00', '--job-id', '195', '--raw', '--subdir', 'DAGS_FOLDER/correction.py', '--cfg-path', '/tmp/tmpp12hzw5z']
[2023-07-11T13:51:21.056+0000] {standard_task_runner.py:85} INFO - Job 195: Subtask save_data
[2023-07-11T13:51:21.272+0000] {task_command.py:410} INFO - Running <TaskInstance: exercice_1.save_data scheduled__2023-07-04T00:00:00+00:00 [running]> on host 1d6232dcfa4d
[2023-07-11T13:51:21.525+0000] {taskinstance.py:1547} INFO - Exporting env vars: AIRFLOW_CTX_DAG_OWNER='***' AIRFLOW_CTX_DAG_ID='exercice_1' AIRFLOW_CTX_TASK_ID='save_data' AIRFLOW_CTX_EXECUTION_DATE='2023-07-04T00:00:00+00:00' AIRFLOW_CTX_TRY_NUMBER='1' AIRFLOW_CTX_DAG_RUN_ID='scheduled__2023-07-04T00:00:00+00:00'
[2023-07-11T13:51:21.538+0000] {taskinstance.py:1824} ERROR - Task failed with exception
Traceback (most recent call last):
  File "/home/airflow/.local/lib/python3.7/site-packages/airflow/operators/python.py", line 181, in execute
    return_value = self.execute_callable()
  File "/home/airflow/.local/lib/python3.7/site-packages/airflow/operators/python.py", line 198, in execute_callable
    return self.python_callable(*self.op_args, **self.op_kwargs)
  File "/opt/airflow/dags/correction.py", line 11, in save_inFile
    .format(context["execution_date"], nb_random())
NameError: name 'nb_random' is not defined
[2023-07-11T13:51:21.594+0000] {taskinstance.py:1350} INFO - Marking task as UP_FOR_RETRY. dag_id=exercice_1, task_id=save_data, execution_date=20230704T000000, start_date=20230711T135120, end_date=20230711T135121
[2023-07-11T13:51:21.651+0000] {standard_task_runner.py:109} ERROR - Failed to execute job 195 for task save_data (name 'nb_random' is not defined; 6851)
[2023-07-11T13:51:21.708+0000] {local_task_job_runner.py:225} INFO - Task exited with return code 1
[2023-07-11T13:51:21.835+0000] {taskinstance.py:2653} INFO - 0 downstream tasks scheduled from follow-on schedule check
[2023-07-11T13:53:41.176+0000] {taskinstance.py:1103} INFO - Dependencies all met for dep_context=non-requeueable deps ti=<TaskInstance: exercice_1.save_data scheduled__2023-07-04T00:00:00+00:00 [queued]>
[2023-07-11T13:53:41.200+0000] {taskinstance.py:1103} INFO - Dependencies all met for dep_context=requeueable deps ti=<TaskInstance: exercice_1.save_data scheduled__2023-07-04T00:00:00+00:00 [queued]>
[2023-07-11T13:53:41.203+0000] {taskinstance.py:1308} INFO - Starting attempt 1 of 2
[2023-07-11T13:53:41.243+0000] {taskinstance.py:1327} INFO - Executing <Task(PythonOperator): save_data> on 2023-07-04 00:00:00+00:00
[2023-07-11T13:53:41.269+0000] {standard_task_runner.py:57} INFO - Started process 6963 to run task
[2023-07-11T13:53:41.289+0000] {standard_task_runner.py:84} INFO - Running: ['***', 'tasks', 'run', 'exercice_1', 'save_data', 'scheduled__2023-07-04T00:00:00+00:00', '--job-id', '217', '--raw', '--subdir', 'DAGS_FOLDER/correction.py', '--cfg-path', '/tmp/tmpckana0zi']
[2023-07-11T13:53:41.294+0000] {standard_task_runner.py:85} INFO - Job 217: Subtask save_data
[2023-07-11T13:53:41.464+0000] {task_command.py:410} INFO - Running <TaskInstance: exercice_1.save_data scheduled__2023-07-04T00:00:00+00:00 [running]> on host 1d6232dcfa4d
[2023-07-11T13:53:41.732+0000] {taskinstance.py:1547} INFO - Exporting env vars: AIRFLOW_CTX_DAG_OWNER='***' AIRFLOW_CTX_DAG_ID='exercice_1' AIRFLOW_CTX_TASK_ID='save_data' AIRFLOW_CTX_EXECUTION_DATE='2023-07-04T00:00:00+00:00' AIRFLOW_CTX_TRY_NUMBER='1' AIRFLOW_CTX_DAG_RUN_ID='scheduled__2023-07-04T00:00:00+00:00'
[2023-07-11T13:53:41.743+0000] {warnings.py:110} WARNING - /home/***/.local/lib/python3.7/site-packages/***/utils/context.py:313: AirflowContextDeprecationWarning: Accessing 'execution_date' from the template is deprecated and will be removed in a future version. Please use 'data_interval_start' or 'logical_date' instead.
  warnings.warn(_create_deprecation_warning(k, replacements))

[2023-07-11T13:53:41.751+0000] {python.py:183} INFO - Done. Returned value was: None
[2023-07-11T13:53:41.773+0000] {taskinstance.py:1350} INFO - Marking task as SUCCESS. dag_id=exercice_1, task_id=save_data, execution_date=20230704T000000, start_date=20230711T135341, end_date=20230711T135341
[2023-07-11T13:53:41.834+0000] {local_task_job_runner.py:225} INFO - Task exited with return code 0
[2023-07-11T13:53:41.891+0000] {taskinstance.py:2653} INFO - 0 downstream tasks scheduled from follow-on schedule check
