[2023-07-11T13:39:23.374+0000] {taskinstance.py:1103} INFO - Dependencies all met for dep_context=non-requeueable deps ti=<TaskInstance: exercice_1.save_data scheduled__2023-07-02T00:00:00+00:00 [queued]>
[2023-07-11T13:39:23.417+0000] {taskinstance.py:1103} INFO - Dependencies all met for dep_context=requeueable deps ti=<TaskInstance: exercice_1.save_data scheduled__2023-07-02T00:00:00+00:00 [queued]>
[2023-07-11T13:39:23.419+0000] {taskinstance.py:1308} INFO - Starting attempt 1 of 2
[2023-07-11T13:39:23.475+0000] {taskinstance.py:1327} INFO - Executing <Task(PythonOperator): save_data> on 2023-07-02 00:00:00+00:00
[2023-07-11T13:39:23.485+0000] {standard_task_runner.py:57} INFO - Started process 6405 to run task
[2023-07-11T13:39:23.502+0000] {standard_task_runner.py:84} INFO - Running: ['***', 'tasks', 'run', 'exercice_1', 'save_data', 'scheduled__2023-07-02T00:00:00+00:00', '--job-id', '128', '--raw', '--subdir', 'DAGS_FOLDER/correction.py', '--cfg-path', '/tmp/tmpblgcgzf5']
[2023-07-11T13:39:23.511+0000] {standard_task_runner.py:85} INFO - Job 128: Subtask save_data
[2023-07-11T13:39:23.727+0000] {task_command.py:410} INFO - Running <TaskInstance: exercice_1.save_data scheduled__2023-07-02T00:00:00+00:00 [running]> on host 1d6232dcfa4d
[2023-07-11T13:39:23.963+0000] {taskinstance.py:1547} INFO - Exporting env vars: AIRFLOW_CTX_DAG_OWNER='***' AIRFLOW_CTX_DAG_ID='exercice_1' AIRFLOW_CTX_TASK_ID='save_data' AIRFLOW_CTX_EXECUTION_DATE='2023-07-02T00:00:00+00:00' AIRFLOW_CTX_TRY_NUMBER='1' AIRFLOW_CTX_DAG_RUN_ID='scheduled__2023-07-02T00:00:00+00:00'
[2023-07-11T13:39:23.976+0000] {taskinstance.py:1824} ERROR - Task failed with exception
Traceback (most recent call last):
  File "/home/airflow/.local/lib/python3.7/site-packages/airflow/operators/python.py", line 181, in execute
    return_value = self.execute_callable()
  File "/home/airflow/.local/lib/python3.7/site-packages/airflow/operators/python.py", line 198, in execute_callable
    return self.python_callable(*self.op_args, **self.op_kwargs)
  File "/opt/airflow/dags/correction.py", line 11, in save_inFile
    .format(context["execution_date"], nb_random())
NameError: name 'nb_random' is not defined
[2023-07-11T13:39:24.012+0000] {taskinstance.py:1350} INFO - Marking task as UP_FOR_RETRY. dag_id=exercice_1, task_id=save_data, execution_date=20230702T000000, start_date=20230711T133923, end_date=20230711T133924
[2023-07-11T13:39:24.038+0000] {standard_task_runner.py:109} ERROR - Failed to execute job 128 for task save_data (name 'nb_random' is not defined; 6405)
[2023-07-11T13:39:24.091+0000] {local_task_job_runner.py:225} INFO - Task exited with return code 1
[2023-07-11T13:39:24.175+0000] {taskinstance.py:2653} INFO - 0 downstream tasks scheduled from follow-on schedule check
[2023-07-11T13:42:05.065+0000] {taskinstance.py:1103} INFO - Dependencies all met for dep_context=non-requeueable deps ti=<TaskInstance: exercice_1.save_data scheduled__2023-07-02T00:00:00+00:00 [queued]>
[2023-07-11T13:42:05.092+0000] {taskinstance.py:1103} INFO - Dependencies all met for dep_context=requeueable deps ti=<TaskInstance: exercice_1.save_data scheduled__2023-07-02T00:00:00+00:00 [queued]>
[2023-07-11T13:42:05.097+0000] {taskinstance.py:1308} INFO - Starting attempt 1 of 2
[2023-07-11T13:42:05.158+0000] {taskinstance.py:1327} INFO - Executing <Task(PythonOperator): save_data> on 2023-07-02 00:00:00+00:00
[2023-07-11T13:42:05.168+0000] {standard_task_runner.py:57} INFO - Started process 6528 to run task
[2023-07-11T13:42:05.190+0000] {standard_task_runner.py:84} INFO - Running: ['***', 'tasks', 'run', 'exercice_1', 'save_data', 'scheduled__2023-07-02T00:00:00+00:00', '--job-id', '149', '--raw', '--subdir', 'DAGS_FOLDER/correction.py', '--cfg-path', '/tmp/tmpk4oaqi7f']
[2023-07-11T13:42:05.197+0000] {standard_task_runner.py:85} INFO - Job 149: Subtask save_data
[2023-07-11T13:42:05.419+0000] {task_command.py:410} INFO - Running <TaskInstance: exercice_1.save_data scheduled__2023-07-02T00:00:00+00:00 [running]> on host 1d6232dcfa4d
[2023-07-11T13:42:05.865+0000] {taskinstance.py:1547} INFO - Exporting env vars: AIRFLOW_CTX_DAG_OWNER='***' AIRFLOW_CTX_DAG_ID='exercice_1' AIRFLOW_CTX_TASK_ID='save_data' AIRFLOW_CTX_EXECUTION_DATE='2023-07-02T00:00:00+00:00' AIRFLOW_CTX_TRY_NUMBER='1' AIRFLOW_CTX_DAG_RUN_ID='scheduled__2023-07-02T00:00:00+00:00'
[2023-07-11T13:42:05.876+0000] {taskinstance.py:1824} ERROR - Task failed with exception
Traceback (most recent call last):
  File "/home/airflow/.local/lib/python3.7/site-packages/airflow/operators/python.py", line 181, in execute
    return_value = self.execute_callable()
  File "/home/airflow/.local/lib/python3.7/site-packages/airflow/operators/python.py", line 198, in execute_callable
    return self.python_callable(*self.op_args, **self.op_kwargs)
  File "/opt/airflow/dags/correction.py", line 11, in save_inFile
    .format(context["execution_date"], nb_random())
NameError: name 'nb_random' is not defined
[2023-07-11T13:42:05.909+0000] {taskinstance.py:1350} INFO - Marking task as UP_FOR_RETRY. dag_id=exercice_1, task_id=save_data, execution_date=20230702T000000, start_date=20230711T134205, end_date=20230711T134205
[2023-07-11T13:42:05.958+0000] {standard_task_runner.py:109} ERROR - Failed to execute job 149 for task save_data (name 'nb_random' is not defined; 6528)
[2023-07-11T13:42:05.985+0000] {local_task_job_runner.py:225} INFO - Task exited with return code 1
[2023-07-11T13:42:06.029+0000] {taskinstance.py:2653} INFO - 0 downstream tasks scheduled from follow-on schedule check
[2023-07-11T13:48:21.130+0000] {taskinstance.py:1103} INFO - Dependencies all met for dep_context=non-requeueable deps ti=<TaskInstance: exercice_1.save_data scheduled__2023-07-02T00:00:00+00:00 [queued]>
[2023-07-11T13:48:21.176+0000] {taskinstance.py:1103} INFO - Dependencies all met for dep_context=requeueable deps ti=<TaskInstance: exercice_1.save_data scheduled__2023-07-02T00:00:00+00:00 [queued]>
[2023-07-11T13:48:21.182+0000] {taskinstance.py:1308} INFO - Starting attempt 1 of 2
[2023-07-11T13:48:21.273+0000] {taskinstance.py:1327} INFO - Executing <Task(PythonOperator): save_data> on 2023-07-02 00:00:00+00:00
[2023-07-11T13:48:21.303+0000] {standard_task_runner.py:57} INFO - Started process 6717 to run task
[2023-07-11T13:48:21.300+0000] {standard_task_runner.py:84} INFO - Running: ['***', 'tasks', 'run', 'exercice_1', 'save_data', 'scheduled__2023-07-02T00:00:00+00:00', '--job-id', '170', '--raw', '--subdir', 'DAGS_FOLDER/correction.py', '--cfg-path', '/tmp/tmphx7jrs0d']
[2023-07-11T13:48:21.325+0000] {standard_task_runner.py:85} INFO - Job 170: Subtask save_data
[2023-07-11T13:48:21.605+0000] {task_command.py:410} INFO - Running <TaskInstance: exercice_1.save_data scheduled__2023-07-02T00:00:00+00:00 [running]> on host 1d6232dcfa4d
[2023-07-11T13:48:22.003+0000] {taskinstance.py:1547} INFO - Exporting env vars: AIRFLOW_CTX_DAG_OWNER='***' AIRFLOW_CTX_DAG_ID='exercice_1' AIRFLOW_CTX_TASK_ID='save_data' AIRFLOW_CTX_EXECUTION_DATE='2023-07-02T00:00:00+00:00' AIRFLOW_CTX_TRY_NUMBER='1' AIRFLOW_CTX_DAG_RUN_ID='scheduled__2023-07-02T00:00:00+00:00'
[2023-07-11T13:48:22.013+0000] {taskinstance.py:1824} ERROR - Task failed with exception
Traceback (most recent call last):
  File "/home/airflow/.local/lib/python3.7/site-packages/airflow/operators/python.py", line 181, in execute
    return_value = self.execute_callable()
  File "/home/airflow/.local/lib/python3.7/site-packages/airflow/operators/python.py", line 198, in execute_callable
    return self.python_callable(*self.op_args, **self.op_kwargs)
  File "/opt/airflow/dags/correction.py", line 11, in save_inFile
    .format(context["execution_date"], nb_random())
NameError: name 'nb_random' is not defined
[2023-07-11T13:48:22.056+0000] {taskinstance.py:1350} INFO - Marking task as UP_FOR_RETRY. dag_id=exercice_1, task_id=save_data, execution_date=20230702T000000, start_date=20230711T134821, end_date=20230711T134822
[2023-07-11T13:48:22.120+0000] {standard_task_runner.py:109} ERROR - Failed to execute job 170 for task save_data (name 'nb_random' is not defined; 6717)
[2023-07-11T13:48:22.173+0000] {local_task_job_runner.py:225} INFO - Task exited with return code 1
[2023-07-11T13:48:22.262+0000] {taskinstance.py:2653} INFO - 0 downstream tasks scheduled from follow-on schedule check
[2023-07-11T13:51:19.718+0000] {taskinstance.py:1103} INFO - Dependencies all met for dep_context=non-requeueable deps ti=<TaskInstance: exercice_1.save_data scheduled__2023-07-02T00:00:00+00:00 [queued]>
[2023-07-11T13:51:19.767+0000] {taskinstance.py:1103} INFO - Dependencies all met for dep_context=requeueable deps ti=<TaskInstance: exercice_1.save_data scheduled__2023-07-02T00:00:00+00:00 [queued]>
[2023-07-11T13:51:19.768+0000] {taskinstance.py:1308} INFO - Starting attempt 1 of 2
[2023-07-11T13:51:19.879+0000] {taskinstance.py:1327} INFO - Executing <Task(PythonOperator): save_data> on 2023-07-02 00:00:00+00:00
[2023-07-11T13:51:19.898+0000] {standard_task_runner.py:57} INFO - Started process 6847 to run task
[2023-07-11T13:51:19.931+0000] {standard_task_runner.py:84} INFO - Running: ['***', 'tasks', 'run', 'exercice_1', 'save_data', 'scheduled__2023-07-02T00:00:00+00:00', '--job-id', '192', '--raw', '--subdir', 'DAGS_FOLDER/correction.py', '--cfg-path', '/tmp/tmp8b2izyiu']
[2023-07-11T13:51:19.946+0000] {standard_task_runner.py:85} INFO - Job 192: Subtask save_data
[2023-07-11T13:51:20.103+0000] {task_command.py:410} INFO - Running <TaskInstance: exercice_1.save_data scheduled__2023-07-02T00:00:00+00:00 [running]> on host 1d6232dcfa4d
[2023-07-11T13:51:20.420+0000] {taskinstance.py:1547} INFO - Exporting env vars: AIRFLOW_CTX_DAG_OWNER='***' AIRFLOW_CTX_DAG_ID='exercice_1' AIRFLOW_CTX_TASK_ID='save_data' AIRFLOW_CTX_EXECUTION_DATE='2023-07-02T00:00:00+00:00' AIRFLOW_CTX_TRY_NUMBER='1' AIRFLOW_CTX_DAG_RUN_ID='scheduled__2023-07-02T00:00:00+00:00'
[2023-07-11T13:51:20.464+0000] {taskinstance.py:1824} ERROR - Task failed with exception
Traceback (most recent call last):
  File "/home/airflow/.local/lib/python3.7/site-packages/airflow/operators/python.py", line 181, in execute
    return_value = self.execute_callable()
  File "/home/airflow/.local/lib/python3.7/site-packages/airflow/operators/python.py", line 198, in execute_callable
    return self.python_callable(*self.op_args, **self.op_kwargs)
  File "/opt/airflow/dags/correction.py", line 11, in save_inFile
    .format(context["execution_date"], nb_random())
NameError: name 'nb_random' is not defined
[2023-07-11T13:51:20.554+0000] {taskinstance.py:1350} INFO - Marking task as UP_FOR_RETRY. dag_id=exercice_1, task_id=save_data, execution_date=20230702T000000, start_date=20230711T135119, end_date=20230711T135120
[2023-07-11T13:51:20.619+0000] {standard_task_runner.py:109} ERROR - Failed to execute job 192 for task save_data (name 'nb_random' is not defined; 6847)
[2023-07-11T13:51:20.682+0000] {local_task_job_runner.py:225} INFO - Task exited with return code 1
[2023-07-11T13:51:20.741+0000] {taskinstance.py:2653} INFO - 0 downstream tasks scheduled from follow-on schedule check
[2023-07-11T13:53:40.575+0000] {taskinstance.py:1103} INFO - Dependencies all met for dep_context=non-requeueable deps ti=<TaskInstance: exercice_1.save_data scheduled__2023-07-02T00:00:00+00:00 [queued]>
[2023-07-11T13:53:40.611+0000] {taskinstance.py:1103} INFO - Dependencies all met for dep_context=requeueable deps ti=<TaskInstance: exercice_1.save_data scheduled__2023-07-02T00:00:00+00:00 [queued]>
[2023-07-11T13:53:40.612+0000] {taskinstance.py:1308} INFO - Starting attempt 1 of 2
[2023-07-11T13:53:40.651+0000] {taskinstance.py:1327} INFO - Executing <Task(PythonOperator): save_data> on 2023-07-02 00:00:00+00:00
[2023-07-11T13:53:40.666+0000] {standard_task_runner.py:57} INFO - Started process 6960 to run task
[2023-07-11T13:53:40.675+0000] {standard_task_runner.py:84} INFO - Running: ['***', 'tasks', 'run', 'exercice_1', 'save_data', 'scheduled__2023-07-02T00:00:00+00:00', '--job-id', '215', '--raw', '--subdir', 'DAGS_FOLDER/correction.py', '--cfg-path', '/tmp/tmpoh7abx4d']
[2023-07-11T13:53:40.683+0000] {standard_task_runner.py:85} INFO - Job 215: Subtask save_data
[2023-07-11T13:53:40.823+0000] {task_command.py:410} INFO - Running <TaskInstance: exercice_1.save_data scheduled__2023-07-02T00:00:00+00:00 [running]> on host 1d6232dcfa4d
[2023-07-11T13:53:41.007+0000] {taskinstance.py:1547} INFO - Exporting env vars: AIRFLOW_CTX_DAG_OWNER='***' AIRFLOW_CTX_DAG_ID='exercice_1' AIRFLOW_CTX_TASK_ID='save_data' AIRFLOW_CTX_EXECUTION_DATE='2023-07-02T00:00:00+00:00' AIRFLOW_CTX_TRY_NUMBER='1' AIRFLOW_CTX_DAG_RUN_ID='scheduled__2023-07-02T00:00:00+00:00'
[2023-07-11T13:53:41.014+0000] {warnings.py:110} WARNING - /home/***/.local/lib/python3.7/site-packages/***/utils/context.py:313: AirflowContextDeprecationWarning: Accessing 'execution_date' from the template is deprecated and will be removed in a future version. Please use 'data_interval_start' or 'logical_date' instead.
  warnings.warn(_create_deprecation_warning(k, replacements))

[2023-07-11T13:53:41.017+0000] {python.py:183} INFO - Done. Returned value was: None
[2023-07-11T13:53:41.041+0000] {taskinstance.py:1350} INFO - Marking task as SUCCESS. dag_id=exercice_1, task_id=save_data, execution_date=20230702T000000, start_date=20230711T135340, end_date=20230711T135341
[2023-07-11T13:53:41.139+0000] {local_task_job_runner.py:225} INFO - Task exited with return code 0
[2023-07-11T13:53:41.195+0000] {taskinstance.py:2653} INFO - 0 downstream tasks scheduled from follow-on schedule check
